Workbook

Sheet Controle de Logistica
A1: Controle de Logistica
B2: Estoque | C2: Uso Mensal
A3: Marcador de Coleta (Unidade) | B3: 52 | C3: 47
A4: Bobina - Cor Branca (Unidade) | B4: 105 | C4: 186
A5: Bobina - Cor Verde (Unidade) | B5: 101 | C5: 30
A6: Ribbon (Unidade) | B6: 158 | C6: 72
A8: Toner Impressora Laser | B8: 7 | C8: 18
A10: Touca (Caixa) | B10: 0 | C10: 3
A11: Luva (Caixa) | B11: 0 | C11: 3
A12: Máscara (Caixa) | B12: 0 | C12: 2
A13: Durex | B13: 14 | C13: 160
A14: Papel Sufite (Pacote) | B14: 13 | C14: 36

Sheet Distribuição
A1: 1 | B1: 2 | C1: 3 | D1: 4 | E1: 5 | F1: 6 | G1: 7 | H1: 8 | I1: 9 | J1: 10 | K1: 11 | L1: 12 | M1: 13 | N1: 14 | O1: 15 | P1: 16 | Q1: 17 | R1: 18 | S1: 19 | T1: 20 | U1: 21 | V1: 22 | W1: 23 | X1: 24 | Y1: 25 | Z1: 26 | AA1: 27 | AB1: 28 | AC1: 29 | AD1: 30 | AE1: 31 | AF1: 32 | AG1: 33 | AH1: 34 | AI1: 35 | AJ1: 36 | AK1: 37 | AL1: 38 | AM1: 39 | AN1: 40 | AO1: 41 | AP1: 42 | AQ1: 43 | AR1: 44 | AS1: 45 | AT1: 46 | AU1: 47 | AV1: 48 | AW1: 49 | AX1: 50 | AY1: 51 | AZ1: 52 | BA1: 53 | BB1: 54 | BC1: 55 | BD1: 56 | BE1: 57 | BF1: 57 | BG1: 58 | BH1: 59 | BI1: 60 | BJ1: 61 | BK1: 62 | BL1: 63
A2: _ | F2: DEPARTAMENTO PESSOAL | AD2: FIOS E CABOS | AP2: COLETOR DE DADOS | BF2: EQUIPAMENTOS ALUGADOS
A3: # | B3: SIGLA | C3: LOJA | D3: DATA | E3: PIV | F3: Toner Impressora Laser | G3: Marcador de Coleta - AZUL ESC | H3: Marcador de Coleta - AZUL CLA | I3: Touca | J3: Luva | K3: Máscara | L3: Grampeador | M3: Durex | N3: Papel Sulfite (Pacote) | O3: Etiqueta Setor 0001 | P3: Etiqueta Setor 1000 | Q3: Etiqueta Setor 2000 | R3: Etiqueta Setor 3000 | S3: Etiqueta Setor 3500 Pereciveis | T3: Etiqueta Setor 4000 | U3: Etiqueta Setor 5000 | V3: Etiqueta Setor 6000 | W3: Etiqueta Setor 7000 | X3: Etiqueta Setor 8000 | Y3: Etiqueta Setor 9000 | Z3: Marcador Coletado | AA3: Calça Térmica | AB3: Capa Térmica | AC3: Cinto de segurança | AD3: Access Point + Fonte | AE3: Router Hap + Fonte | AF3: Switch Poe Pro | AG3: Cabo Power | AH3: Cabo USB (Impressora) | AI3: Filtro de Linha | AJ3: Transformador | AK3: Cabo Transformador | AL3: Teste Voltagem | AM3: Adaptador | AN3: Extensão | AO3: Cabo de Rede (RJ45) | AP3: Coletor de Dados | AQ3: Carregador de Bateria | AR3: Fonte Carregador de Bateria | AS3: Bateria Coletor | AT3: Carregador Tipo C | AU3: Cabo USB (Berço) | AV3: Berço | AW3: Mouse | AX3: Placa 3G | AY3: Tablet | AZ3: Notebook | BA3: Fonte Noteebook | BB3: Impressora Laser | BC3: Escada | BD3: Aranha Pra Escada | BE3: Balança | BF3: Coletor de Dados MC 3190 | BG3: Carregador de Bateria MC 3190 | BH3: Fonte Carregador de Bateria MC 3190 | BI3: Bateria Coletor MC 3190 | BJ3: Fonte Carregador Berço MC 3190 | BK3: Berço Coletor MC 3190 | BL3: Cabo de USB Berço MC 3190
A4: =CONCATENATE(B4,C4)
A5: =CONCATENATE(B5,C5)
A6: =CONCATENATE(B6,C6)
A7: =CONCATENATE(B7,C7)
A8: =CONCATENATE(B8,C8)
A9: =CONCATENATE(B9,C9)
A10: =CONCATENATE(B10,C10)
A11: =CONCATENATE(B11,C11)
A12: =CONCATENATE(B12,C12)
A13: =CONCATENATE(B13,C13)
A14: =CONCATENATE(B14,C14)
A15: =CONCATENATE(B15,C15)
... A741: =CONCATENATE(B741,C741)

Sheet Check - List
D1: CHECK LIST DE EQUIPAMENTOS | Z1: =CONCATENATE(C3,E3)
B3: CLIENTE | F3: DATA | G3: =VLOOKUP(Z1,Distribuição!A:D,4,FALSE) -> 0
B5: ENDEREÇO | C5: =VLOOKUP(Z1,[1]Agosto!A$1:N$65537,5,FALSE) -> 45139
B7: BAIRRO | C7: =VLOOKUP(Z1,[1]Agosto!A$1:N$65537,6,FALSE) -> TERÇA | F7: CIDADE: | G7: =VLOOKUP(Z1,[1]Agosto!A$1:N$65537,7,FALSE) -> 0 | J7: ATENÇÃO
B9: # | C9: Descrição | E9: Envio QUANTIDADE | F9: Saída LOGISTICA | G9: Conferencia Loja | I9: Retorno LOGISTICA | J9: após ser notificado pela logistica do equipamento faltante (s). | K9: de todos os equipamento a logistica conferido, serei responsavel pela reposiçao dos mesmos em ate 15 dias corridos | L9: Eu................................................................. Responsavel pelo inventario descrito neste check list estou ciente que o não retorno
G10: Entrada | H10: Saída
B11: DEPARTAMENTO PESSOAL | C11: Toner Impressora Laser | E11: =VLOOKUP($Z$1,Distribuição!A:BD,6,FALSE) -> 0
C12: Marcador de Coleta - AZUL ESCURO | E12: =VLOOKUP($Z$1,Distribuição!A:BD,7,FALSE) -> 0
C13: Marcador de Coleta - AZUL CLARO | E13: =VLOOKUP($Z$1,Distribuição!A:BD,8,FALSE) -> 0
C14: Touca | E14: =VLOOKUP($Z$1,Distribuição!A:BD,9,FALSE) -> 0
C15: Luva | E15: =VLOOKUP($Z$1,Distribuição!A:BD,10,FALSE) -> 0
C16: Máscara | E16: =VLOOKUP($Z$1,Distribuição!A:BD,11,FALSE) -> 0
C17: Grampeador | E17: =VLOOKUP($Z$1,Distribuição!A:BD,12,FALSE) -> 0
C18: Durex | E18: =VLOOKUP($Z$1,Distribuição!A:BD,13,FALSE) -> 0
A19: OBS. 35 COLETORES SENDO 15 ANDROID, 4 CARREGADOR E 8 CABO USB TIPO C | C19: Papel Sulfite (Pacote) | E19: =VLOOKUP($Z$1,Distribuição!A:BD,14,FALSE) -> 0
C20: Etiqueta Setor 0001 | E20: =VLOOKUP($Z$1,Distribuição!A:BD,15,FALSE) -> 0
C21: Etiqueta Setor 1000 | E21: =VLOOKUP($Z$1,Distribuição!A:BD,16,FALSE) -> 0
C22: Etiqueta Setor 2000 | E22: =VLOOKUP($Z$1,Distribuição!A:BD,17,FALSE) -> 0
C23: Etiqueta Setor 3000 | E23: =VLOOKUP($Z$1,Distribuição!A:BD,18,FALSE) -> 0
C24: Etiqueta Setor 3500 - Peso Variável | E24: =VLOOKUP($Z$1,Distribuição!A:BD,19,FALSE) -> 0
C25: Etiqueta Setor 4000 | E25: =VLOOKUP($Z$1,Distribuição!A:BD,20,FALSE) -> 0
C26: Etiqueta Setor 5000 | E26: =VLOOKUP($Z$1,Distribuição!A:BD,21,FALSE) -> 0
C27: Etiqueta Setor 6000 | E27: =VLOOKUP($Z$1,Distribuição!A:BD,22,FALSE) -> 0
C28: Etiqueta Setor 7000 | E28: =VLOOKUP($Z$1,Distribuição!A:BD,23,FALSE) -> 0
C29: Etiqueta Setor 8000 | E29: =VLOOKUP($Z$1,Distribuição!A:BD,24,FALSE) -> 0
C30: Etiqueta Setor 9000 | E30: =VLOOKUP($Z$1,Distribuição!A:BD,25,FALSE) -> 0
C31: Marcador Coletado | E31: =VLOOKUP($Z$1,Distribuição!A:BD,26,FALSE) -> 0
C32: Calça Térmica | E32: =VLOOKUP($Z$1,Distribuição!A:BD,27,FALSE) -> 0
C33: Capa Térmica | E33: =VLOOKUP($Z$1,Distribuição!A:BD,28,FALSE) -> 0
C34: Capacete | E34: =VLOOKUP($Z$1,Distribuição!A:BL,29,FALSE) -> 0
C35: Botas do 33/48 | E35: 0
C36: Cinto de segurança | E36: =VLOOKUP($Z$1,Distribuição!A:BL,29,FALSE) -> 0
B37: FIOS E CABOS | C37: Access Point + Fonte | E37: =VLOOKUP($Z$1,Distribuição!A:BD,30,FALSE) -> 0
C38: Router Hap + Fonte | E38: =VLOOKUP($Z$1,Distribuição!A:BD,31,FALSE) -> 0
C39: Switch Poe Pro | E39: =VLOOKUP($Z$1,Distribuição!A:BD,32,FALSE) -> 0
C40: Cabo Power | E40: =VLOOKUP($Z$1,Distribuição!A:BD,33,FALSE) -> 0
C41: Cabo USB (Impressora) | E41: =VLOOKUP($Z$1,Distribuição!A:BD,34,FALSE) -> 0
C42: Filtro de Linha | E42: =VLOOKUP($Z$1,Distribuição!A:BD,35,FALSE) -> 0
C43: Transformador | E43: =VLOOKUP($Z$1,Distribuição!A:BD,36,FALSE) -> 0
C44: Cabo Transformador | E44: =VLOOKUP($Z$1,Distribuição!A:BD,37,FALSE) -> 0
...

Sheet Declaração
J1: =CONCATENATE(C4,E4)
E2: DECLARAÇÃO DE RETIRADA DE EQUIPAMENTOS
B4: CLIENTE | F4: DATA
B6: ENDEREÇO
B8: BAIRRO
B10: HORARIO DE ENTREGA | E10: HORARIO DE INICIO
B12: P.ENCONTRO JURUBATUBA | E12: P.ENCONTRO PEDRO II
B14: TRANSPORTE
B15: A REVELAÇÃO ASSESSORIA EMPRESARIAL S/S LTDA, CNPJ: 04.304.329/0001-05 vem através desta declarar o a entrega e retirada dos equipamentos abaixo:
B27: DEPARTAMENTO PESSOAL
B29: FIOS E CABOS
B31: COLETOR DE DADOS
B33: IMPRESSORA
B35: ESCADA
B37: BALANÇA
B39: EXTENSOR DE REDE / CARRINHO
B41: QUANTIDADE DE VOLUME | F41: =SUM(F27,F29,F31,F33,F35,F37,F39) -> 0

Sheet Planilha3
F2: PESSOAS | G2: COLETOR
B3: CFX | C3: 1044 | D3: 44993 | E3: T | F3: 2 | G3: 3
B4: MEL | C4: 34 | D4: 44993 | E4: CA | F4: 6 | G4: 10
B5: MEL | C5: 20 | D5: 44993 | E5: CA | F5: 5 | G5: 10
B6: MEL | C6: 43 | D6: 44993 | E6: CA | F6: 5 | G6: 10
B7: MEL | C7: 34 | D7: 44993 | E7: T | F7: 33 | G7: 21
B8: MEL | C8: 20 | D8: 44993 | E8: T | F8: 27 | G8: 15
B9: MEL | C9: 43 | D9: 44993 | E9: T | F9: 25 | G9: 13
B10: CDG | C10: 862 | D10: 44993 | E10: T | F10: 8 | G10: 8
B11: CFO | C11: 106 | D11: 44993 | E11: PNA | F11: 39 | G11: 39
B12: CFX | C12: 678 | D12: 44993 | E12: T | F12: 5 | G12: 6
B13: MEL | C13: 11 | D13: 44993 | E13: T | F13: 31 | G13: 29
B14: PMO | C14: 13 | D14: 44993 | E14: T | F14: 5 | G14: 6
... B18: CFX | C18: 962 | D18: 44993 | E18: T | F18: 6 | G18: 7
B19: STM | C19: S705 | D19: 44993 | E19: T | F19: 35 | G19: 33
B20: MEL | C20: 30 | D20: 44994 | E20: CA | F20: 7 | G20: 7
B21: MEL | C21: 51 | D21: 44994 | E21: CA | F21: 6 | G21: 6
F22: TOTAL | G22: =SUM(G3:G21) -> 261
B23: TOTAL DE COLETORES EM USO
B24: MC - 65 | D24: 241
B25: SKORPIO X3 | D25: 20

Sheet Planilha2
A1: DESCRIÇÃO | B1: São Paulo | D1: Equipamentos em manutenção | E1: Equipamentos danificados (SUCATA) | F1: Equipamentos extraviados | G1: TOTAL
B2: Ativo | C2: Inativo
A3: NOTEBOOKS DELL i3 | B3: 22 | G3: 22
A4: NOTEBOOKS DELL i5 | B4: 8 | G4: 8
A5: IMPRESSORA SAMSUNG 2165 | E5: 4 | G5: 4
A6: IMPRESSORA SAMSUNG 2020 | B6: 14 | E6: 18 | G6: 32
A7: IMPRESSORA HP 107 | B7: 12 | G7: 12
A8: CASE P/ IMPRESSORAS | B8: 25 | D8: 1 | G8: 26
A9: COLETOR SCORPION X3 | B9: 4 | D9: 11 | G9: 15
A10: COLETOR SCORPION X4 | B10: 1 | D10: 4 | G10: 5
A11: CARREGADOR DE BATERIAS (p/ SCORPION) | B11: 1 | G11: 1
A12: CASE P/ COLETOR SCORPION
A13: BATERIA RESERVA (3000) - SCORPION | B13: 20 | G13: 20
A14: BATERIA RESERVA (5200) - SCORPION | B14: 6 | G14: 6
A15: COLETOR MC659B | B15: 243 | D15: 3 | E15: 9 | F15: 42 | G15: 297
A16: CASE P/ COLETOR MC659B (10P) | B16: 17 | G16: 17
A17: CASE P/ COLETOR MC659B (10P c/ Tampa grande) | B17: 10 | G17: 10
A18: CASE P/ COLETOR MC659B (15P) | B18: 10 | G18: 10
A19: BATERIA RESERVA (2400) - MC659B | B19: 55 | G19: 55
A20: BATERIA RESERVA (3600) - MC659B | B20: 551 | G20: 551
A21: CARREGADOR DE BATERIAS PLUS (p/ MC659B) | B21: 29 | G21: 29
A22: CARREGADOR DE BATERIAS (BERÇO p/ MC659B) | B22: 16 | G22: 16
A23: ROTEADORES (HAP SERIES) | B23: 18 | G23: 18
A24: ACCESS POINT (ANTENA BRANCA) | B24: 9 | G24: 9
A25: SWITCH UBIQUITI | B25: 3 | G25: 3
A26: CINTO DE SEGURANÇA (EPI) | B26: 18 | G26: 18
A27: CAPACETE DE SEGURANÇA (EPI) | B27: 10 | G27: 10
A28: MODEM 3G (GSM) | B28: 20 | G28: 20
A29: TRANSFORMADOR | B29: 30
A30: BALANÇA 300KG | B30: 30 | D30: 7 | E30: 3 | G30: 40
A31: ESCADA DE ALUMÍNIO | B31: 145 | D31: 11 | G31: 156

Sheet Preparação de Lojas
B2: PREPARAÇÃO DE LOJAS
B3: CLIENTE | C3: DATA | D3: LOCAL | E3: TERMINO PREPARAÇÃO | F3: HORARIO DA ENTREGA | G3: INICIO DO INVENTÁRIO
B4: PET 010011 | C4: 41578 | D4: CD Anhaguera | E4: 0.625 | F4: 0.70833333 | G4: Dia 01/11 às 9:00

Sheet Planilha1
A1: LA | B1: LOJA | C1: DATA | D1: BAIRRO | E1: CIDADE | F1: UF | G1: TIPO | H1: EQUIPAMENTOS
A2: JAU | B2: 9 | C2: 44095 | D2: VILA MARCELINO | E2: SÃO CARLOS | F2: SP SUL | G2: LO | H2: 4
A3: JAU | B3: 13 | C3: 44095 | D3: REDENÇÃO | E3: SÃO CARLOS | F3: SP SUL | G3: LO | H3: 3
A4: JAU | B4: 18 | C4: 44095 | D4: CIDADE JARDIM | E4: SÃO CARLOS | F4: SP SUL | G4: LO | H4: 3
A5: JAU | B5: 32 | C5: 44095 | D5: VILA COSTA DO SOL | E5: SÃO CARLOS | F5: SP SUL | G5: LO | H5: 6
H6: 16
A7: JAU | B7: 6 | C7: 44096 | D7: VILA PRADO | E7: SÃO CARLOS | F7: SP SUL | G7: LO | H7: 4
A8: JAU | B8: 7 | C8: 44096 | D8: CENTRO - PADRE TEIXEIRA | E8: SÃO CARLOS | F8: SP SUL | G8: LO | H8: 3
A9: JAU | B9: 10 | C9: 44096 | D9: VILA VISTA ALEGRE | E9: SÃO CARLOS | F9: SP SUL | G9: LO | H9: 4
A10: JAU | B10: 22 | C10: 44096 | D10: CENTRO - VISCONDE DE INHAÚMA | E10: SÃO CARLOS | F10: SP SUL | G10: LO | H10: 6
H11: 17
A12: JAU | B12: 29 | C12: 44097 | D12: VILA STEOLA | E12: PIRASSUNUNGA | F12: SP SUL | G12: LO | H12: 5
A13: JAU | B13: 25 | C13: 44097 | D13: SÃO DIMAS | E13: PIRACICABA | F13: SP SUL | G13: LO | H13: 5
A14: JAU | B14: 28 | C14: 44097 | D14: CENTRO | E14: PIRACICABA | F14: SP SUL | G14: LO | H14: 4
A15: JAU | B15: 34 | C15: 44097 | D15: VILA REZENDE | E15: PIRACICABA | F15: SP SUL | G15: LO | H15: 5
H16: 19

Sheet Check - List - Detalhado
A1: Check - List - Detalhado
A2: Tipo | B2: Coletor | C2: Carregador de Bateria | D2: Bateria | E2: Cabo de Dados | F2: Berço/Com..
A3: MC 65 | B3: 22 | C3: 3 | D3: 12 | E3: 2 | F3: 0
A5: SKORPIO X3 | B5: 68 | C5: 6 | D5: 24 | E5: 0 | F5: 2
A7: SKORPIO X4 | B7: 1 | D7: 0 | E7: 0 | F7: 0
A9: Notebook | B9: 1 | D9: Fonte Notebook | F9: 1 | K9: Equipamentos Para ir pro Rio de Janeiro
K10: 10 | L10: Coletores
K11: 2 | L11: Carregadores
K12: 2 | L12: Fonte para Carregador
K13: 2 | L13: Cabo Power
K14: 8 | L14: Baterias

Sheet Plan2
A1: DATA | B1: CLIENTE | C1: ENDEREÇO | D1: BAIRRO | E1: KM

Sheet Plan3
A1: CONTROLE DE KILOMETRAGEM | E1: DATA | F1: TOTAL | G1: CONTROLE DE KILOMETRAGEM | K1: DATA | L1: TOTAL
A2: KM SAIDA | C2: KM CHEGADA | G2: KM SAIDA | I2: KM CHEGADA
A3: KM SAIDA | C3: KM CHEGADA | G3: KM SAIDA | I3: KM CHEGADA
A4: KM SAIDA | C4: KM CHEGADA | G4: KM SAIDA | I4: KM CHEGADA
A5: KM SAIDA | C5: KM CHEGADA | G5: KM SAIDA | I5: KM CHEGADA
A6: KM SAIDA | C6: KM CHEGADA | G6: KM SAIDA | I6: KM CHEGADA
A7: KM SAIDA | C7: KM CHEGADA | G7: KM SAIDA | I7: KM CHEGADA
A8: KM SAIDA | C8: KM CHEGADA | G8: KM SAIDA | I8: KM CHEGADA
A9: KM SAIDA | C9: KM CHEGADA | G9: KM SAIDA | I9: KM CHEGADA
A10: KM SAIDA | C10: KM CHEGADA | G10: KM SAIDA | I10: KM CHEGADA
A11: KM SAIDA | C11: KM CHEGADA | G11: KM SAIDA | I11: KM CHEGADA
A12: KM SAIDA | C12: KM CHEGADA | G12: KM SAIDA | I12: KM CHEGADA
A13: KM SAIDA | C13: KM CHEGADA | G13: KM SAIDA | I13: KM CHEGADA
... A36: KM SAIDA | C36: KM CHEGADA | G36: KM SAIDA | I36: KM CHEGADA

Sheet Plan4

Sheet Plan5
A1: Distribuição | E1: Coletor | F1: Total
A2: AKK | B2: 3 | C2: 42249 | D2: 15 | E2: 20
A3: CCA | B3: 4 | C3: 42249 | D3: 6 | E3: 7
A4: PTL | B4: 12 | C4: 42249 | D4: 8 | E4: 9 | F4: 107
A5: PTL | B5: 37 | C5: 42249 | D5: 9 | E5: 10
A6: PTL | B6: 18 | C6: 42249 | D6: 10 | E6: 11
A7: PET | B7: 04 0006 | C7: 42249 | D7: 50 | E7: 50
A8: AKK | B8: 3_2 | C8: 42250 | D8: 20 | E8: 12
A9: CCA | B9: 3 | C9: 42250 | D9: 6 | E9: 7
A10: PTL | B10: 17 | C10: 42250 | D10: 8 | E10: 9 | F10: 107
A11: PTL | B11: 21 | C11: 42250 | D11: 12 | E11: 13
A12: PTL | B12: 43 | C12: 42250 | D12: 8 | E12: 9
A13: CEC | B13: 2 | C13: 42250 | D13: 44 | E13: 37

Sheet Plan6
